Traceback (most recent call last):
  File "/home/nils/miniconda3/envs/agi-jb/lib/python3.9/site-packages/jupyter_cache/executors/utils.py", line 51, in single_nb_execution
    executenb(
  File "/home/nils/miniconda3/envs/agi-jb/lib/python3.9/site-packages/nbclient/client.py", line 1117, in execute
    return NotebookClient(nb=nb, resources=resources, km=km, **kwargs).execute()
  File "/home/nils/miniconda3/envs/agi-jb/lib/python3.9/site-packages/nbclient/util.py", line 78, in wrapped
    return just_run(coro(*args, **kwargs))
  File "/home/nils/miniconda3/envs/agi-jb/lib/python3.9/site-packages/nbclient/util.py", line 57, in just_run
    return loop.run_until_complete(coro)
  File "/home/nils/miniconda3/envs/agi-jb/lib/python3.9/asyncio/base_events.py", line 642, in run_until_complete
    return future.result()
  File "/home/nils/miniconda3/envs/agi-jb/lib/python3.9/site-packages/nbclient/client.py", line 558, in async_execute
    await self.async_execute_cell(
  File "/home/nils/miniconda3/envs/agi-jb/lib/python3.9/site-packages/nbclient/client.py", line 862, in async_execute_cell
    self._check_raise_for_error(cell, exec_reply)
  File "/home/nils/miniconda3/envs/agi-jb/lib/python3.9/site-packages/nbclient/client.py", line 765, in _check_raise_for_error
    raise CellExecutionError.from_cell_and_msg(cell, exec_reply_content)
nbclient.exceptions.CellExecutionError: An error occurred while executing the following cell:
------------------
from matplotlib import pyplot as plt 
import pandas as pd

x_neu_list = [offset_coordinate(x_start, 100) for i in range(1,1000)]
y_neu_list = [offset_coordinate(y_start, 100) for i in range(1,1000)]

fig = plt.scatter(x_neu_list,y_neu_list)

fig.axis("equal")
------------------

[0;31m---------------------------------------------------------------------------[0m
[0;31mAttributeError[0m                            Traceback (most recent call last)
[0;32m/tmp/ipykernel_21582/4169789651.py[0m in [0;36m<module>[0;34m[0m
[1;32m      7[0m [0mfig[0m [0;34m=[0m [0mplt[0m[0;34m.[0m[0mscatter[0m[0;34m([0m[0mx_neu_list[0m[0;34m,[0m[0my_neu_list[0m[0;34m)[0m[0;34m[0m[0;34m[0m[0m
[1;32m      8[0m [0;34m[0m[0m
[0;32m----> 9[0;31m [0mfig[0m[0;34m.[0m[0maxis[0m[0;34m([0m[0;34m"equal"[0m[0;34m)[0m[0;34m[0m[0;34m[0m[0m
[0m
[0;31mAttributeError[0m: 'PathCollection' object has no attribute 'axis'
AttributeError: 'PathCollection' object has no attribute 'axis'

