Traceback (most recent call last):
  File "/opt/hostedtoolcache/Python/3.7.12/x64/lib/python3.7/site-packages/jupyter_cache/executors/utils.py", line 56, in single_nb_execution
    record_timing=False,
  File "/opt/hostedtoolcache/Python/3.7.12/x64/lib/python3.7/site-packages/nbclient/client.py", line 1093, in execute
    return NotebookClient(nb=nb, resources=resources, km=km, **kwargs).execute()
  File "/opt/hostedtoolcache/Python/3.7.12/x64/lib/python3.7/site-packages/nbclient/util.py", line 84, in wrapped
    return just_run(coro(*args, **kwargs))
  File "/opt/hostedtoolcache/Python/3.7.12/x64/lib/python3.7/site-packages/nbclient/util.py", line 62, in just_run
    return loop.run_until_complete(coro)
  File "/opt/hostedtoolcache/Python/3.7.12/x64/lib/python3.7/asyncio/base_events.py", line 587, in run_until_complete
    return future.result()
  File "/opt/hostedtoolcache/Python/3.7.12/x64/lib/python3.7/site-packages/nbclient/client.py", line 560, in async_execute
    cell, index, execution_count=self.code_cells_executed + 1
  File "/opt/hostedtoolcache/Python/3.7.12/x64/lib/python3.7/site-packages/nbclient/client.py", line 854, in async_execute_cell
    self._check_raise_for_error(cell, exec_reply)
  File "/opt/hostedtoolcache/Python/3.7.12/x64/lib/python3.7/site-packages/nbclient/client.py", line 756, in _check_raise_for_error
    raise CellExecutionError.from_cell_and_msg(cell, exec_reply_content)
nbclient.exceptions.CellExecutionError: An error occurred while executing the following cell:
------------------
base = wald.explore(column = "Wald_text", cmap = my_cmap)
zeckenstiche.explore(m = base, color = "red")

------------------

[0;31m---------------------------------------------------------------------------[0m
[0;31mModuleNotFoundError[0m                       Traceback (most recent call last)
[0;32m/opt/hostedtoolcache/Python/3.7.12/x64/lib/python3.7/site-packages/geopandas/explore.py[0m in [0;36m_explore[0;34m(df, column, cmap, color, m, tiles, attr, tooltip, popup, highlight, categorical, legend, scheme, k, vmin, vmax, width, height, categories, classification_kwds, control_scale, marker_type, marker_kwds, style_kwds, highlight_kwds, missing_kwds, tooltip_kwds, popup_kwds, legend_kwds, **kwargs)[0m
[1;32m    250[0m     [0;32mtry[0m[0;34m:[0m[0;34m[0m[0;34m[0m[0m
[0;32m--> 251[0;31m         [0;32mimport[0m [0mbranca[0m [0;32mas[0m [0mbc[0m[0;34m[0m[0;34m[0m[0m
[0m[1;32m    252[0m         [0;32mimport[0m [0mfolium[0m[0;34m[0m[0;34m[0m[0m

[0;31mModuleNotFoundError[0m: No module named 'branca'

During handling of the above exception, another exception occurred:

[0;31mImportError[0m                               Traceback (most recent call last)
[0;32m/tmp/ipykernel_2095/1063094436.py[0m in [0;36m<module>[0;34m[0m
[0;32m----> 1[0;31m [0mbase[0m [0;34m=[0m [0mwald[0m[0;34m.[0m[0mexplore[0m[0;34m([0m[0mcolumn[0m [0;34m=[0m [0;34m"Wald_text"[0m[0;34m,[0m [0mcmap[0m [0;34m=[0m [0mmy_cmap[0m[0;34m)[0m[0;34m[0m[0;34m[0m[0m
[0m[1;32m      2[0m [0mzeckenstiche[0m[0;34m.[0m[0mexplore[0m[0;34m([0m[0mm[0m [0;34m=[0m [0mbase[0m[0;34m,[0m [0mcolor[0m [0;34m=[0m [0;34m"red"[0m[0;34m)[0m[0;34m[0m[0;34m[0m[0m

[0;32m/opt/hostedtoolcache/Python/3.7.12/x64/lib/python3.7/site-packages/geopandas/geodataframe.py[0m in [0;36mexplore[0;34m(self, *args, **kwargs)[0m
[1;32m   1856[0m     [0;32mdef[0m [0mexplore[0m[0;34m([0m[0mself[0m[0;34m,[0m [0;34m*[0m[0margs[0m[0;34m,[0m [0;34m**[0m[0mkwargs[0m[0;34m)[0m[0;34m:[0m[0;34m[0m[0;34m[0m[0m
[1;32m   1857[0m         [0;34m"""Interactive map based on folium/leaflet.js"""[0m[0;34m[0m[0;34m[0m[0m
[0;32m-> 1858[0;31m         [0;32mreturn[0m [0m_explore[0m[0;34m([0m[0mself[0m[0;34m,[0m [0;34m*[0m[0margs[0m[0;34m,[0m [0;34m**[0m[0mkwargs[0m[0;34m)[0m[0;34m[0m[0;34m[0m[0m
[0m[1;32m   1859[0m [0;34m[0m[0m
[1;32m   1860[0m     [0;32mdef[0m [0msjoin[0m[0;34m([0m[0mself[0m[0;34m,[0m [0mdf[0m[0;34m,[0m [0;34m*[0m[0margs[0m[0;34m,[0m [0;34m**[0m[0mkwargs[0m[0;34m)[0m[0;34m:[0m[0;34m[0m[0;34m[0m[0m

[0;32m/opt/hostedtoolcache/Python/3.7.12/x64/lib/python3.7/site-packages/geopandas/explore.py[0m in [0;36m_explore[0;34m(df, column, cmap, color, m, tiles, attr, tooltip, popup, highlight, categorical, legend, scheme, k, vmin, vmax, width, height, categories, classification_kwds, control_scale, marker_type, marker_kwds, style_kwds, highlight_kwds, missing_kwds, tooltip_kwds, popup_kwds, legend_kwds, **kwargs)[0m
[1;32m    257[0m     [0;32mexcept[0m [0;34m([0m[0mImportError[0m[0;34m,[0m [0mModuleNotFoundError[0m[0;34m)[0m[0;34m:[0m[0;34m[0m[0;34m[0m[0m
[1;32m    258[0m         raise ImportError(
[0;32m--> 259[0;31m             [0;34m"The 'folium', 'matplotlib' and 'mapclassify' packages are required for "[0m[0;34m[0m[0;34m[0m[0m
[0m[1;32m    260[0m             [0;34m"'explore()'. You can install them using "[0m[0;34m[0m[0;34m[0m[0m
[1;32m    261[0m             [0;34m"'conda install -c conda-forge folium matplotlib mapclassify' "[0m[0;34m[0m[0;34m[0m[0m

[0;31mImportError[0m: The 'folium', 'matplotlib' and 'mapclassify' packages are required for 'explore()'. You can install them using 'conda install -c conda-forge folium matplotlib mapclassify' or 'pip install folium matplotlib mapclassify'.
ImportError: The 'folium', 'matplotlib' and 'mapclassify' packages are required for 'explore()'. You can install them using 'conda install -c conda-forge folium matplotlib mapclassify' or 'pip install folium matplotlib mapclassify'.

